Workbook

Sheet Info & Guidelines
A1: Verifiable Credential Infrastructure - Test Case Template
A3: Description: | B3: This template provides a comprehensive test suite for Verifiable Credential (VC) infrastructure implementations based on W3C Verifiable Credentials standards. It covers all critical aspects of credential issuance, verification, revocation, and management.
A5: Purpose: | B5: To provide service providers, governments, and implementers with a standardized test framework for validating their VC systems before production deployment.
A7: Standards Covered: | B7: • W3C Verifiable Credentials Data Model 1.1 & 2.0 • W3C Decentralized Identifiers (DIDs) • StatusList2021 (Revocation) • JSON Web Tokens (JWT) for VCs • JSON-LD & SD-JWT formats • OpenID4VCI (OpenID for Verifiable Credential Issuance)
A14: Test Priority Levels:
A15: Priority 1 (Must Have) | B15: Critical tests required for production. These cover security, signature verification, revocation, and trust validation.
A16: Priority 2 (Should Have) | B16: Important tests for robustness including cross-border interoperability, offline scenarios, and audit logging.
A17: Priority 3 (Nice to Have) | B17: Enhanced quality tests including performance, privacy protection, and advanced security scenarios.
A19: Test Type Definitions:
A20: Unit | B20: Fast, isolated tests of individual functions. Run on every code commit.
A21: Integration | B21: Tests interaction between components. Use real databases and services in test environment.
A22: E2E | B22: End-to-end tests of complete workflows. Test full system from UI to database.
A23: Manual | B23: Tests requiring human judgment, security expertise, or physical devices.
A25: How to Use This Template:
B26: 1. Review all test cases across the different sheets 2. Customize test cases to match your specific implementation (credential types, DIDs, trust registry) 3. Mark test cases as applicable or not applicable to your use case 4. Add implementation-specific test data in the Preconditions and Test Steps 5. Execute tests according to the recommended Test Type (Unit, Integration, E2E, Manual) 6. Update Status column as you execute tests (Not Started, In Progress, Passed, Failed, Blocked) 7. Document any deviations or additional test cases in the Notes column
A34: Version: | B34: 1.0
A35: Last Updated: | B35: 45992
A36: License: | B36: Creative Commons CC-BY 4.0 - Free to use and adapt with attribution

Sheet Quick Reference
A1: Verifiable Credential Test Case Quick Reference
A3: Test Execution Guide
A4: STEP 1: Review Test Scope • Start with "Priority 1 - Critical" sheet (must pass before production) • Focus on: Signature verification, revocation, DID resolution, trust registry STEP 2: Customize Test Cases • Replace generic values with your implementation specifics: - DID methods (did:web, did:key, etc.) - Issuer names and DIDs - Credential schemas and types - Trust registry URLs STEP 3: Execute by Type • Unit Tests: Run on every commit • Integration Tests: Run before deployment • E2E Tests: Run for releases • Manual Tests: Security audits STEP 4: Track Progress • Update Status column • Use Notes for defect tracking • Monitor Summary Dashboard
A22: Test Coverage by Component
A23: Component | B23: Description
A24: Signature Verification | B24: Cryptographic validation, tamper detection, key management
A25: DID Resolution | B25: DID resolution, document validation, lifecycle management
A26: Trust Registry | B26: Issuer trust validation, authorization, regional registries
A27: Revocation Management | B27: StatusList2021, cache handling, offline scenarios
A28: Credential Issuance | B28: Single and bulk issuance, schema management
A29: Credential Verification | B29: QR scan/upload, verification workflows
A30: Mobile Wallet | B30: Download, storage, sharing, backup, security
A31: Cross-Border | B31: International credential verification, interoperability

Sheet Test Summary Dashboard
A1: Test Summary Dashboard
A3: Test Cases by Priority
A4: Priority Level | B4: Total Tests | C4: Passed | D4: Failed | E4: Not Started
A5: Priority 1 (Must Have) | B5: 45 | C5: =COUNTIFS('All Test Cases'!B:B,"Priority 1 (Must Have)",'All Test Cases'!J:J,"Passed") -> 0 | D5: =COUNTIFS('All Test Cases'!B:B,"Priority 1 (Must Have)",'All Test Cases'!J:J,"Failed") -> 0 | E5: =COUNTIFS('All Test Cases'!B:B,"Priority 1 (Must Have)",'All Test Cases'!J:J,"Not Started") -> 34
A6: Priority 2 (Should Have) | B6: 46 | C6: =COUNTIFS('All Test Cases'!B:B,"Priority 2 (Should Have)",'All Test Cases'!J:J,"Passed") -> 0 | D6: =COUNTIFS('All Test Cases'!B:B,"Priority 2 (Should Have)",'All Test Cases'!J:J,"Failed") -> 0 | E6: =COUNTIFS('All Test Cases'!B:B,"Priority 2 (Should Have)",'All Test Cases'!J:J,"Not Started") -> 48
A7: Priority 3 (Nice to Have) | B7: 36 | C7: =COUNTIFS('All Test Cases'!B:B,"Priority 3 (Nice to Have)",'All Test Cases'!J:J,"Passed") -> 0 | D7: =COUNTIFS('All Test Cases'!B:B,"Priority 3 (Nice to Have)",'All Test Cases'!J:J,"Failed") -> 0 | E7: =COUNTIFS('All Test Cases'!B:B,"Priority 3 (Nice to Have)",'All Test Cases'!J:J,"Not Started") -> 20
A9: Test Cases by Category
A10: Category | B10: Total Tests | C10: Passed | D10: Failed | E10: Not Started
A11: Signature Verification | B11: =COUNTIF('All Test Cases'!C:C,"Signature Verification") -> 6 | C11: =COUNTIFS('All Test Cases'!C:C,"Signature Verification",'All Test Cases'!J:J,"Passed") -> 0 | D11: =COUNTIFS('All Test Cases'!C:C,"Signature Verification",'All Test Cases'!J:J,"Failed") -> 0 | E11: =COUNTIFS('All Test Cases'!C:C,"Signature Verification",'All Test Cases'!J:J,"Not Started") -> 6
A12: Revocation Management | B12: =COUNTIF('All Test Cases'!C:C,"Revocation Management") -> 7 | C12: =COUNTIFS('All Test Cases'!C:C,"Revocation Management",'All Test Cases'!J:J,"Passed") -> 0 | D12: =COUNTIFS('All Test Cases'!C:C,"Revocation Management",'All Test Cases'!J:J,"Failed") -> 0 | E12: =COUNTIFS('All Test Cases'!C:C,"Revocation Management",'All Test Cases'!J:J,"Not Started") -> 7
A13: Expiration & Validity | B13: =COUNTIF('All Test Cases'!C:C,"Expiration & Validity") -> 6 | C13: =COUNTIFS('All Test Cases'!C:C,"Expiration & Validity",'All Test Cases'!J:J,"Passed") -> 0 | D13: =COUNTIFS('All Test Cases'!C:C,"Expiration & Validity",'All Test Cases'!J:J,"Failed") -> 0 | E13: =COUNTIFS('All Test Cases'!C:C,"Expiration & Validity",'All Test Cases'!J:J,"Not Started") -> 6
A14: DID Resolution | B14: =COUNTIF('All Test Cases'!C:C,"DID Resolution") -> 7 | C14: =COUNTIFS('All Test Cases'!C:C,"DID Resolution",'All Test Cases'!J:J,"Passed") -> 0 | D14: =COUNTIFS('All Test Cases'!C:C,"DID Resolution",'All Test Cases'!J:J,"Failed") -> 0 | E14: =COUNTIFS('All Test Cases'!C:C,"DID Resolution",'All Test Cases'!J:J,"Not Started") -> 7
A15: Trust Registry | B15: =COUNTIF('All Test Cases'!C:C,"Trust Registry") -> 8 | C15: =COUNTIFS('All Test Cases'!C:C,"Trust Registry",'All Test Cases'!J:J,"Passed") -> 0 | D15: =COUNTIFS('All Test Cases'!C:C,"Trust Registry",'All Test Cases'!J:J,"Failed") -> 0 | E15: =COUNTIFS('All Test Cases'!C:C,"Trust Registry",'All Test Cases'!J:J,"Not Started") -> 8
A16: Cross-Border Interoperability | B16: =COUNTIF('All Test Cases'!C:C,"Cross-Border Interoperability") -> 6 | C16: =COUNTIFS('All Test Cases'!C:C,"Cross-Border Interoperability",'All Test Cases'!J:J,"Passed") -> 0 | D16: =COUNTIFS('All Test Cases'!C:C,"Cross-Border Interoperability",'All Test Cases'!J:J,"Failed") -> 0 | E16: =COUNTIFS('All Test Cases'!C:C,"Cross-Border Interoperability",'All Test Cases'!J:J,"Not Started") -> 6
A17: Schema Validation | B17: =COUNTIF('All Test Cases'!C:C,"Schema Validation") -> 2 | C17: =COUNTIFS('All Test Cases'!C:C,"Schema Validation",'All Test Cases'!J:J,"Passed") -> 0 | D17: =COUNTIFS('All Test Cases'!C:C,"Schema Validation",'All Test Cases'!J:J,"Failed") -> 0 | E17: =COUNTIFS('All Test Cases'!C:C,"Schema Validation",'All Test Cases'!J:J,"Not Started") -> 2
A18: Offline Scenarios | B18: =COUNTIF('All Test Cases'!C:C,"Offline Scenarios") -> 3 | C18: =COUNTIFS('All Test Cases'!C:C,"Offline Scenarios",'All Test Cases'!J:J,"Passed") -> 0 | D18: =COUNTIFS('All Test Cases'!C:C,"Offline Scenarios",'All Test Cases'!J:J,"Failed") -> 0 | E18: =COUNTIFS('All Test Cases'!C:C,"Offline Scenarios",'All Test Cases'!J:J,"Not Started") -> 3
A19: Security & Privacy | B19: =COUNTIF('All Test Cases'!C:C,"Security & Privacy") -> 10 | C19: =COUNTIFS('All Test Cases'!C:C,"Security & Privacy",'All Test Cases'!J:J,"Passed") -> 0 | D19: =COUNTIFS('All Test Cases'!C:C,"Security & Privacy",'All Test Cases'!J:J,"Failed") -> 0 | E19: =COUNTIFS('All Test Cases'!C:C,"Security & Privacy",'All Test Cases'!J:J,"Not Started") -> 10
A20: Performance & Scale | B20: =COUNTIF('All Test Cases'!C:C,"Performance & Scale") -> 3 | C20: =COUNTIFS('All Test Cases'!C:C,"Performance & Scale",'All Test Cases'!J:J,"Passed") -> 0 | D20: =COUNTIFS('All Test Cases'!C:C,"Performance & Scale",'All Test Cases'!J:J,"Failed") -> 0 | E20: =COUNTIFS('All Test Cases'!C:C,"Performance & Scale",'All Test Cases'!J:J,"Not Started") -> 3
A23: Test Cases by Test Type
A24: Test Type | B24: Total Tests | C24: Percentage
A25: Unit | B25: 28 | C25: =28/127 -> 0.22047244
A26: Integration | B26: 60 | C26: =60/127 -> 0.47244094
A27: E2E | B27: 23 | C27: =23/127 -> 0.18110236
A28: Manual | B28: 16 | C28: =16/127 -> 0.12598425

Sheet All Test Cases
A1: Test Case ID | B1: Priority | C1: Category | D1: Component | E1: Test Case Description | F1: Preconditions | G1: Test Steps | H1: Expected Results | I1: Test Type | J1: Status | K1: Notes
A2: VC-SIG-001 | B2: Priority 1 (Must Have) | C2: Signature Verification | D2: Cryptographic Validation | E2: Verify rejection of credential with tampered signature | F2: Valid credential with modified signature value | G2: 1. Obtain a valid verifiable credential 2. Modify the signature field (proof.jws or proof.proofValue) 3. Attempt to verify the credential using the verification API | H2: Verification fails with error message "Invalid signature" or similar. System rejects credential. | I2: Unit | J2: Not Started | K2: Tests core cryptographic verification
A3: VC-SIG-002 | B3: Priority 1 (Must Have) | C3: Signature Verification | D3: Cryptographic Validation | E3: Verify rejection of credential with tampered data | F3: Valid credential with modified credentialSubject data but original signature intact | G3: 1. Obtain a valid credential 2. Modify a field in credentialSubject (e.g., name or ID) 3. Keep the original signature unchanged 4. Attempt to verify the credential | H3: Signature verification fails because data hash does not match signature. Credential rejected. | I3: Unit | J3: Not Started | K3: Ensures integrity protection
A4: VC-SIG-003 | B4: Priority 1 (Must Have) | C4: Signature Verification | D4: Key Management | E4: Verify credential with expired signing key | F4: Credential signed with a key that has passed its expiration date | G4: 1. Present credential signed with expired key 2. System checks key expiration in DID document or key metadata 3. Attempt verification | H4: Verification fails with "Signing key expired" error | I4: Unit | J4: Not Started | K4: Key lifecycle validation
A5: VC-SIG-004 | B5: Priority 1 (Must Have) | C5: Signature Verification | D5: Key Management | E5: Verify credential with revoked signing key | F5: Issuer has revoked the key used to sign the credential | G5: 1. Present credential signed with now-revoked key 2. System checks key revocation status 3. Attempt verification | H5: Verification fails with "Signing key revoked" error | I5: Unit | J5: Not Started | K5: Key revocation handling
A6: VC-SIG-005 | B6: Priority 1 (Must Have) | C6: Signature Verification | D6: Key Management | E6: Verify credential after issuer key rotation | F6: Credential signed with old key, issuer has rotated to new key | G6: 1. Present credential signed with previous valid key 2. Verify against current issuer DID document 3. Old key should still be in DID document history | H6: Verification succeeds if old key is still valid in DID document | I6: Unit | J6: Not Started | K6: Key rotation backward compatibility
A7: VC-SIG-006 | B7: Priority 1 (Must Have) | C7: Signature Verification | D7: Algorithm Validation | E7: Verify credential with unsupported signature algorithm | F7: Credential signed with algorithm not in supported list | G7: 1. Present credential with unsupported "alg" (e.g., RS256 if only ES256K supported) 2. Attempt verification | H7: Verification fails with "Unsupported algorithm" error | I7: Unit | J7: Not Started | K7: Algorithm allowlist enforcement
A8: VC-REV-001 | B8: Priority 1 (Must Have) | C8: Revocation Management | D8: StatusList2021 | E8: Verify handling when StatusList2021 endpoint is unreachable | F8: Valid credential with credentialStatus pointing to unreachable endpoint | G8: 1. Present valid credential 2. StatusList2021 URL returns 404 or 503 3. Attempt verification | H8: System behavior depends on policy: Either fail closed (reject credential) or allow with warning "Revocation status unknown" | I8: Integration | J8: Not Started | K8: Network resilience for revocation
A9: VC-REV-002 | B9: Priority 1 (Must Have) | C9: Revocation Management | D9: StatusList2021 | E9: Verify handling when StatusList2021 returns malformed data | F9: Status list endpoint returns invalid or corrupted bitstring | G9: 1. Present credential 2. StatusList endpoint returns corrupted/invalid data 3. Attempt verification | H9: Verification fails with "Cannot determine revocation status" error | I9: Integration | J9: Not Started | K9: Data integrity validation
A10: VC-REV-003 | B10: Priority 1 (Must Have) | C10: Revocation Management | D10: StatusList2021 | E10: Verify handling when StatusList2021 times out | F10: Status list endpoint has high latency (>30 seconds) | G10: 1. Present credential 2. StatusList request times out 3. Attempt verification | H10: Verification fails or succeeds with warning based on timeout policy | I10: Integration | J10: Not Started | K10: Timeout handling
A11: VC-REV-004 | B11: Priority 1 (Must Have) | C11: Revocation Management | D11: Caching | E11: Verify stale revocation cache handling | F11: Cached revocation list is outdated | G11: 1. System has cached revocation list from 24 hours ago 2. Credential was revoked 1 hour ago 3. Present credential for verification | H11: System fetches fresh revocation list, detects revocation, rejects credential | I11: Integration | J11: Not Started | K11: Cache freshness validation
A12: VC-REV-005 | B12: Priority 1 (Must Have) | C12: Revocation Management | D12: Timing | E12: Verify credential revoked between issuance and first verification | F12: Credential issued and immediately revoked before first use | G12: 1. Issue credential 2. Revoke credential within same minute 3. User presents credential for first time | H12: Verification detects revocation, credential rejected | I12: Integration | J12: Not Started | K12: Race condition handling
... A40: VC-XBORDER-005 | B40: Priority 2 (Should Have) | C40: Cross-Border Interoperability | D40: Identifier Formats | E40: Verify credential with foreign credential subject identifier | F40: Credential uses foreign national ID format | G40: 1. Present credential with foreign identifier format 2. Verify in local system | H40: Foreign identifier format accepted and validated | I40: E2E | J40: Not Started | K40: Identifier diversity
A41: VC-XBORDER-006 | B41: Priority 2 (Should Have) | C41: Cross-Border Interoperability | D41: Timezone | E41: Verify time zone handling across countries | F41: Credential issued in UTC, verified in different timezone | G41: 1. Issue credential in Country A (UTC-4) 2. Verify in Country B (UTC-5) 3. Check time-based validations | H41: Time-based validations work correctly across zones | I41: E2E | J41: Not Started
A42: VC-OFFLINE-001 | B42: Priority 2 (Should Have) | C42: Offline Scenarios | D42: Cached Verification | E42: Verify credential with cached DID document | F42: Verifier has no internet, DID document cached | G42: 1. Disconnect verifier from network 2. Present credential 3. Verify using cached issuer DID document | H42: Verification succeeds using cached data | I42: Integration | J42: Not Started
A43: VC-OFFLINE-002 | B43: Priority 2 (Should Have) | C43: Offline Scenarios | D43: Partial Verification | E43: Verify credential without revocation check (offline mode) | F43: Verifier offline, cannot check revocation list | G43: 1. Present credential in offline mode 2. System cannot reach StatusList2021 endpoint 3. Attempt verification | H43: Verification succeeds with warning "Revocation not checked" | I43: Integration | J43: Not Started
A44: VC-OFFLINE-003 | B44: Priority 2 (Should Have) | C44: Offline Scenarios | D44: Self-Contained | E44: Verify embedded proof credential offline | F44: Credential with all proof data embedded | G44: 1. Present self-contained credential 2. Verify completely offline | H44: Full verification succeeds without network | I44: Integration | J44: Not Started
A45: VC-KEYROT-001 | B45: Priority 2 (Should Have) | C45: Key Management | D45: Key Rotation | E45: Verify credential after issuer key rotation with old key still valid | F45: Issuer rotated keys, old key still in DID document | G45: 1. Credential signed with key-1 2. Issuer now uses key-2 3. Key-1 still in DID document 4. Verify credential | H45: Verification succeeds (key-1 still trusted) | I45: Integration | J45: Not Started
A46: VC-KEYROT-002 | B46: Priority 2 (Should Have) | C46: Key Management | D46: Deprecated Keys | E46: Verify credential with deprecated key | F46: Signing key marked as deprecated in DID document | G46: 1. Present credential signed with deprecated key 2. DID document shows key status = "deprecated" 3. Attempt verification | H46: Verification succeeds with warning or fails based on policy | I46: Integration | J46: Not Started
A47: VC-SCHEMA-001 | B47: Priority 2 (Should Have) | C47: Schema Validation | D47: Conformance | E47: Verify credential not matching declared schema | F47: Credential references schema but does not conform | G47: 1. Credential declares credentialSchema 2. Missing required field in schema 3. Attempt verification | H47: Verification fails with "Schema validation failed" error | I47: Unit | J47: Not Started
A48: VC-SCHEMA-002 | B48: Priority 2 (Should Have) | C48: Schema Validation | D48: Schema Resolution | E48: Verify credential with unreachable schema URL | F48: credentialSchema URL returns 404 | G48: 1. Present credential with unreachable schema URL 2. Schema URL returns 404 3. Attempt verification | H48: Verification fails or succeeds with warning based on policy | I48: Integration | J48: Not Started
A49: VC-AUDIT-001 | B49: Priority 2 (Should Have) | C49: Audit & Logging | D49: Completeness | E49: Verify all verification attempts are logged | F49: System configured for audit logging | G49: 1. Perform 10 verification attempts (5 success, 5 failures) 2. Query audit log 3. Check for all 10 entries | H49: All attempts logged with timestamp, result, credential ID | I49: Integration | J49: Not Started
A50: VC-AUDIT-002 | B50: Priority 2 (Should Have) | C50: Audit & Logging | D50: Privacy | E50: Verify PII exclusion from logs | F50: Credential contains personal information | G50: 1. Verify credential with personal data 2. Check audit logs 3. Verify no PII present | H50: Logs contain hashed credential ID only, no PII | I50: Integration | J50: Not Started
A51: VC-AUDIT-003 | B51: Priority 2 (Should Have) | C51: Audit & Logging | D51: Error Details | E51: Verify failed verification details logged | F51: Verification fails for multiple reasons | G51: 1. Attempt verification of invalid credential 2. Check audit log for failure reason | H51: Log includes specific failure reason (revoked, expired, invalid sig) | I51: Integration | J51: Not Started
A52: VC-PERF-001 | B52: Priority 3 (Nice to Have) | C52: Performance & Scale | D52: Throughput | E52: Verify concurrent verification throughput | F52: 100 concurrent verifiers | G52: 1. Simulate 100 verifiers checking credentials simultaneously 2. Measure response time 3. Check for errors | H52: All verifications complete within 5 seconds, no errors | I52: E2E | J52: Not Started
... A57: VC-PRIV-003 | B57: Priority 3 (Nice to Have) | C57: Security & Privacy | D57: Selective Disclosure | E57: Verify selective disclosure (if using SD-JWT) | F57: SD-JWT credential with multiple claims | G57: 1. Create presentation with only specific fields 2. Exclude other fields 3. Verify presentation | H57: Only disclosed claims verified, others not revealed | I57: Integration | J57: Not Started
A58: VC-MOBILE-SEC-001 | B58: Priority 3 (Nice to Have) | C58: Security & Privacy | D58: Device Security | E58: Verify rooted/jailbroken device detection | F58: App installed on compromised device | G58: 1. Install wallet on rooted Android device 2. Launch app 3. Check security validation | H58: App detects root, displays warning or refuses to run | I58: Manual | J58: Not Started | K58: Requires physical device
A59: VC-MOBILE-SEC-002 | B59: Priority 3 (Nice to Have) | C59: Security & Privacy | D59: Biometrics | E59: Verify biometric authentication failure handling | F59: Biometric auth enabled | G59: 1. Attempt biometric auth 5 times with wrong fingerprint 2. Check fallback mechanism | H59: Falls back to PIN after failed attempts | I59: Manual | J59: Not Started | K59: Requires physical device
A60: VC-MOBILE-SEC-003 | B60: Priority 3 (Nice to Have) | C60: Security & Privacy | D60: Key Storage | E60: Verify secure key storage | F60: Wallet generates private keys | G60: 1. Generate key pair in wallet 2. Check key storage location 3. Attempt to extract key | H60: Keys stored in Keychain/Keystore, cannot be extracted | I60: Manual | J60: Not Started | K60: Requires forensics
A61: VC-MOBILE-SEC-004 | B61: Priority 3 (Nice to Have) | C61: Security & Privacy | D61: Screen Capture | E61: Verify screen capture prevention | F61: Sensitive credential displayed | G61: 1. Display credential with PII 2. Attempt screenshot 3. Check if blocked | H61: Screenshot blocked or image shows blank screen | I61: Manual | J61: Not Started | K61: Requires physical device
A62: VC-NEG-001 | B62: Priority 3 (Nice to Have) | C62: Security & Privacy | D62: SQL Injection | E62: Verify SQL injection in search | F62: Search functionality in system | G62: 1. Enter search query with SQL injection attempt 2. Submit search | H62: Query properly sanitized, no SQL execution | I62: Manual | J62: Not Started | K62: Security testing
A63: VC-NEG-002 | B63: Priority 3 (Nice to Have) | C63: Security & Privacy | D63: XSS | E63: Verify XSS in credential display | F63: Credential with malicious script in field | G63: 1. Issue credential with script in name field 2. Display credential | H63: Script properly escaped, not executed | I63: Manual | J63: Not Started | K63: Security testing
A64: VC-NEG-003 | B64: Priority 3 (Nice to Have) | C64: Security & Privacy | D64: CSRF | E64: Verify CSRF protection | F64: Admin portal action | G64: 1. Craft malicious request without CSRF token 2. Submit to action endpoint | H64: Request rejected, CSRF protection active | I64: Manual | J64: Not Started | K64: Security testing
A65: VC-COMP-001 | B65: Priority 3 (Nice to Have) | C65: Compliance | D65: Data Protection | E65: Verify right to erasure (GDPR/similar) | F65: User requests credential deletion | G65: 1. User submits deletion request 2. System removes credential and related data 3. Check audit logs 4. Attempt to retrieve deleted data | H65: All personal data removed, audit log shows deletion event | I65: E2E | J65: Not Started
A66: VC-COMP-002 | B66: Priority 3 (Nice to Have) | C66: Compliance | D66: Data Retention | E66: Verify data retention policy enforcement | F66: Audit logs older than retention period | G66: 1. System runs retention policy job 2. Old logs archived/deleted 3. Verify compliance | H66: Old logs archived, retention policy enforced | I66: Integration | J66: Not Started
A67: VC-BIZ-001 | B67: Priority 3 (Nice to Have) | C67: Business Logic | D67: Versioning | E67: Verify credential superseding | F67: Updated credential issued for same subject | G67: 1. Issue credential v1 2. Issue credential v2 (updated information) 3. Both credentials valid 4. Determine which is current | H67: System identifies v2 as current, v1 as superseded | I67: Unit | J67: Not Started
A68: VC-BIZ-002 | B68: Priority 3 (Nice to Have) | C68: Business Logic | D68: Usage Restrictions | E68: Verify conditional credential validity | F68: Credential valid only in certain contexts | G68: 1. Credential includes usage restriction metadata 2. Attempt use outside allowed context | H68: Verifier enforces usage restrictions | I68: Unit | J68: Not Started
A69: VC-RESIL-001 | B69: Priority 3 (Nice to Have) | C69: Resilience | D69: Failover | E69: Verify database failover | F69: Primary database fails | G69: 1. Simulate primary DB failure 2. System fails over to replica 3. Continue credential operations | H69: Seamless failover, operations continue | I69: Integration | J69: Not Started
A70: VC-RESIL-002 | B70: Priority 3 (Nice to Have) | C70: Resilience | D70: Backup & Restore | E70: Verify credential recovery from backup | F70: Wallet backup exists | G70: 1. Delete wallet app 2. Reinstall app 3. Restore from backup | H70: All credentials restored successfully | I70: E2E | J70: Not Started
A71: VC-ISS-001 | B71: Priority 2 (Should Have) | C71: Credential Issuance | D71: Authentication | E71: Verify successful login to issuance portal with valid credentials | F71: User has valid issuer credentials | G71: 1. Enter correct username 2. Enter correct password 3. Click Sign In | H71: User redirected to dashboard/home page | I71: E2E | J71: Not Started | K71: From existing test TC001
...

Sheet Priority 1 - Critical
A1: Test Case ID | B1: Priority | C1: Category | D1: Component | E1: Test Case Description | F1: Preconditions | G1: Test Steps | H1: Expected Results | I1: Test Type | J1: Status | K1: Notes
A2: VC-SIG-001 | B2: Priority 1 (Must Have) | C2: Signature Verification | D2: Cryptographic Validation | E2: Verify rejection of credential with tampered signature | F2: Valid credential with modified signature value | G2: 1. Obtain a valid verifiable credential 2. Modify the signature field (proof.jws or proof.proofValue) 3. Attempt to verify the credential using the verification API | H2: Verification fails with error message "Invalid signature" or similar. System rejects credential. | I2: Unit | J2: Not Started | K2: Tests core cryptographic verification
A3: VC-SIG-002 | B3: Priority 1 (Must Have) | C3: Signature Verification | D3: Cryptographic Validation | E3: Verify rejection of credential with tampered data | F3: Valid credential with modified credentialSubject data but original signature intact | G3: 1. Obtain a valid credential 2. Modify a field in credentialSubject (e.g., name or ID) 3. Keep the original signature unchanged 4. Attempt to verify the credential | H3: Signature verification fails because data hash does not match signature. Credential rejected. | I3: Unit | J3: Not Started | K3: Ensures integrity protection
A4: VC-SIG-003 | B4: Priority 1 (Must Have) | C4: Signature Verification | D4: Key Management | E4: Verify credential with expired signing key | F4: Credential signed with a key that has passed its expiration date | G4: 1. Present credential signed with expired key 2. System checks key expiration in DID document or key metadata 3. Attempt verification | H4: Verification fails with "Signing key expired" error | I4: Unit | J4: Not Started | K4: Key lifecycle validation
A5: VC-SIG-004 | B5: Priority 1 (Must Have) | C5: Signature Verification | D5: Key Management | E5: Verify credential with revoked signing key | F5: Issuer has revoked the key used to sign the credential | G5: 1. Present credential signed with now-revoked key 2. System checks key revocation status 3. Attempt verification | H5: Verification fails with "Signing key revoked" error | I5: Unit | J5: Not Started | K5: Key revocation handling
A6: VC-SIG-005 | B6: Priority 1 (Must Have) | C6: Signature Verification | D6: Key Management | E6: Verify credential after issuer key rotation | F6: Credential signed with old key, issuer has rotated to new key | G6: 1. Present credential signed with previous valid key 2. Verify against current issuer DID document 3. Old key should still be in DID document history | H6: Verification succeeds if old key is still valid in DID document | I6: Unit | J6: Not Started | K6: Key rotation backward compatibility
A7: VC-SIG-006 | B7: Priority 1 (Must Have) | C7: Signature Verification | D7: Algorithm Validation | E7: Verify credential with unsupported signature algorithm | F7: Credential signed with algorithm not in supported list | G7: 1. Present credential with unsupported "alg" (e.g., RS256 if only ES256K supported) 2. Attempt verification | H7: Verification fails with "Unsupported algorithm" error | I7: Unit | J7: Not Started | K7: Algorithm allowlist enforcement
A8: VC-REV-001 | B8: Priority 1 (Must Have) | C8: Revocation Management | D8: StatusList2021 | E8: Verify handling when StatusList2021 endpoint is unreachable | F8: Valid credential with credentialStatus pointing to unreachable endpoint | G8: 1. Present valid credential 2. StatusList2021 URL returns 404 or 503 3. Attempt verification | H8: System behavior depends on policy: Either fail closed (reject credential) or allow with warning "Revocation status unknown" | I8: Integration | J8: Not Started | K8: Network resilience for revocation
A9: VC-REV-002 | B9: Priority 1 (Must Have) | C9: Revocation Management | D9: StatusList2021 | E9: Verify handling when StatusList2021 returns malformed data | F9: Status list endpoint returns invalid or corrupted bitstring | G9: 1. Present credential 2. StatusList endpoint returns corrupted/invalid data 3. Attempt verification | H9: Verification fails with "Cannot determine revocation status" error | I9: Integration | J9: Not Started | K9: Data integrity validation
A10: VC-REV-003 | B10: Priority 1 (Must Have) | C10: Revocation Management | D10: StatusList2021 | E10: Verify handling when StatusList2021 times out | F10: Status list endpoint has high latency (>30 seconds) | G10: 1. Present credential 2. StatusList request times out 3. Attempt verification | H10: Verification fails or succeeds with warning based on timeout policy | I10: Integration | J10: Not Started | K10: Timeout handling
A11: VC-REV-004 | B11: Priority 1 (Must Have) | C11: Revocation Management | D11: Caching | E11: Verify stale revocation cache handling | F11: Cached revocation list is outdated | G11: 1. System has cached revocation list from 24 hours ago 2. Credential was revoked 1 hour ago 3. Present credential for verification | H11: System fetches fresh revocation list, detects revocation, rejects credential | I11: Integration | J11: Not Started | K11: Cache freshness validation
A12: VC-REV-005 | B12: Priority 1 (Must Have) | C12: Revocation Management | D12: Timing | E12: Verify credential revoked between issuance and first verification | F12: Credential issued and immediately revoked before first use | G12: 1. Issue credential 2. Revoke credential within same minute 3. User presents credential for first time | H12: Verification detects revocation, credential rejected | I12: Integration | J12: Not Started | K12: Race condition handling
... A35: VC-TRUST-008 | B35: Priority 1 (Must Have) | C35: Trust Registry | D35: Versioning | E35: Verify trust framework version compatibility | F35: Credential issued under older trust framework version | G35: 1. Present credential with trustFramework = "FRAMEWORK-v1.0" 2. Current system uses "FRAMEWORK-v2.0" 3. Attempt verification | H35: System checks compatibility matrix, accepts if backward compatible | I35: Integration | J35: Not Started | K35: Version compatibility

Sheet Priority 2 - Important
A1: Test Case ID | B1: Priority | C1: Category | D1: Component | E1: Test Case Description | F1: Preconditions | G1: Test Steps | H1: Expected Results | I1: Test Type | J1: Status | K1: Notes
A2: VC-XBORDER-001 | B2: Priority 2 (Should Have) | C2: Cross-Border Interoperability | D2: International Verification | E2: Verify credential from foreign country | F2: Valid credential from foreign issuer | G2: 1. Present credential from Country B to Country A verifier 2. Verify issuer DID is resolvable 3. Check against regional trust registry | H2: Credential verified successfully, issuer validated in regional registry | I2: E2E | J2: Not Started | K2: Critical for regional integration
A3: VC-XBORDER-002 | B3: Priority 2 (Should Have) | C3: Cross-Border Interoperability | D3: Internationalization | E3: Verify credential with multiple language fields | F3: Credential with both English and other language text | G3: 1. Present credential with multilingual fields 2. Verify in system with different locale 3. Check proper display | H3: System displays appropriate language, both validate correctly | I3: E2E | J3: Not Started | K3: Multilingual support
A4: VC-XBORDER-003 | B4: Priority 2 (Should Have) | C4: Cross-Border Interoperability | D4: Schema Compatibility | E4: Verify credential schema from different country | F4: Foreign country uses slightly different schema version | G4: 1. Present credential with schema v1.1 2. Local system expects schema v1.0 3. Schemas are compatible (superset) | H4: Verification succeeds with schema compatibility check | I4: E2E | J4: Not Started | K4: Schema interoperability
A5: VC-XBORDER-004 | B5: Priority 2 (Should Have) | C5: Cross-Border Interoperability | D5: Registry Hierarchy | E5: Verify regional vs national trust registry precedence | F5: Issuer in regional registry but not national registry | G5: 1. Present credential from regional issuer 2. Check both registries 3. Determine trust based on policy | H5: Clear precedence rules applied (regional trust accepted) | I5: E2E | J5: Not Started | K5: Registry hierarchy
A6: VC-XBORDER-005 | B6: Priority 2 (Should Have) | C6: Cross-Border Interoperability | D6: Identifier Formats | E6: Verify credential with foreign credential subject identifier | F6: Credential uses foreign national ID format | G6: 1. Present credential with foreign identifier format 2. Verify in local system | H6: Foreign identifier format accepted and validated | I6: E2E | J6: Not Started | K6: Identifier diversity
A7: VC-XBORDER-006 | B7: Priority 2 (Should Have) | C7: Cross-Border Interoperability | D7: Timezone | E7: Verify time zone handling across countries | F7: Credential issued in UTC, verified in different timezone | G7: 1. Issue credential in Country A (UTC-4) 2. Verify in Country B (UTC-5) 3. Check time-based validations | H7: Time-based validations work correctly across zones | I7: E2E | J7: Not Started
A8: VC-OFFLINE-001 | B8: Priority 2 (Should Have) | C8: Offline Scenarios | D8: Cached Verification | E8: Verify credential with cached DID document | F8: Verifier has no internet, DID document cached | G8: 1. Disconnect verifier from network 2. Present credential 3. Verify using cached issuer DID document | H8: Verification succeeds using cached data | I8: Integration | J8: Not Started
A9: VC-OFFLINE-002 | B9: Priority 2 (Should Have) | C9: Offline Scenarios | D9: Partial Verification | E9: Verify credential without revocation check (offline mode) | F9: Verifier offline, cannot check revocation list | G9: 1. Present credential in offline mode 2. System cannot reach StatusList2021 endpoint 3. Attempt verification | H9: Verification succeeds with warning "Revocation not checked" | I9: Integration | J9: Not Started
A10: VC-OFFLINE-003 | B10: Priority 2 (Should Have) | C10: Offline Scenarios | D10: Self-Contained | E10: Verify embedded proof credential offline | F10: Credential with all proof data embedded | G10: 1. Present self-contained credential 2. Verify completely offline | H10: Full verification succeeds without network | I10: Integration | J10: Not Started
A11: VC-KEYROT-001 | B11: Priority 2 (Should Have) | C11: Key Management | D11: Key Rotation | E11: Verify credential after issuer key rotation with old key still valid | F11: Issuer rotated keys, old key still in DID document | G11: 1. Credential signed with key-1 2. Issuer now uses key-2 3. Key-1 still in DID document 4. Verify credential | H11: Verification succeeds (key-1 still trusted) | I11: Integration | J11: Not Started
A12: VC-KEYROT-002 | B12: Priority 2 (Should Have) | C12: Key Management | D12: Deprecated Keys | E12: Verify credential with deprecated key | F12: Signing key marked as deprecated in DID document | G12: 1. Present credential signed with deprecated key 2. DID document shows key status = "deprecated" 3. Attempt verification | H12: Verification succeeds with warning or fails based on policy | I12: Integration | J12: Not Started
A13: VC-SCHEMA-001 | B13: Priority 2 (Should Have) | C13: Schema Validation | D13: Conformance | E13: Verify credential not matching declared schema | F13: Credential references schema but does not conform | G13: 1. Credential declares credentialSchema 2. Missing required field in schema 3. Attempt verification | H13: Verification fails with "Schema validation failed" error | I13: Unit | J13: Not Started
A14: VC-SCHEMA-002 | B14: Priority 2 (Should Have) | C14: Schema Validation | D14: Schema Resolution | E14: Verify credential with unreachable schema URL | F14: credentialSchema URL returns 404 | G14: 1. Present credential with unreachable schema URL 2. Schema URL returns 404 3. Attempt verification | H14: Verification fails or succeeds with warning based on policy | I14: Integration | J14: Not Started
A15: VC-AUDIT-001 | B15: Priority 2 (Should Have) | C15: Audit & Logging | D15: Completeness | E15: Verify all verification attempts are logged | F15: System configured for audit logging | G15: 1. Perform 10 verification attempts (5 success, 5 failures) 2. Query audit log 3. Check for all 10 entries | H15: All attempts logged with timestamp, result, credential ID | I15: Integration | J15: Not Started
A16: VC-AUDIT-002 | B16: Priority 2 (Should Have) | C16: Audit & Logging | D16: Privacy | E16: Verify PII exclusion from logs | F16: Credential contains personal information | G16: 1. Verify credential with personal data 2. Check audit logs 3. Verify no PII present | H16: Logs contain hashed credential ID only, no PII | I16: Integration | J16: Not Started
A17: VC-AUDIT-003 | B17: Priority 2 (Should Have) | C17: Audit & Logging | D17: Error Details | E17: Verify failed verification details logged | F17: Verification fails for multiple reasons | G17: 1. Attempt verification of invalid credential 2. Check audit log for failure reason | H17: Log includes specific failure reason (revoked, expired, invalid sig) | I17: Integration | J17: Not Started
A18: VC-ISS-001 | B18: Priority 2 (Should Have) | C18: Credential Issuance | D18: Authentication | E18: Verify successful login to issuance portal with valid credentials | F18: User has valid issuer credentials | G18: 1. Enter correct username 2. Enter correct password 3. Click Sign In | H18: User redirected to dashboard/home page | I18: E2E | J18: Not Started | K18: From existing test TC001
A19: VC-ISS-002 | B19: Priority 2 (Should Have) | C19: Credential Issuance | D19: Authentication | E19: Validate error for incorrect password | F19: User has valid username | G19: 1. Enter valid username 2. Enter incorrect password 3. Click Login | H19: Error message: "Invalid username or password" | I19: E2E | J19: Not Started | K19: From existing test TC002
A20: VC-ISS-003 | B20: Priority 2 (Should Have) | C20: Credential Issuance | D20: Security | E20: Validate password masking | F20: User is on login page | G20: 1. Enter password in password field 2. Check if characters are masked 3. Click eye icon to toggle visibility | H20: Password masked by default, visible when eye icon clicked | I20: E2E | J20: Not Started | K20: From existing test TC003
A21: VC-ISS-004 | B21: Priority 2 (Should Have) | C21: Credential Issuance | D21: Issuer Management | E21: Verify new issuer can be added successfully | F21: User logged into admin portal on Issuer List page | G21: 1. Click Add Issuer button 2. Enter valid Issuer Name 3. Enter valid Display Name 4. Provide Issuer Logo URL 5. Enter Issuer Admin Email 6. Click Create | H21: New issuer created, username and temporary password displayed | I21: E2E | J21: Not Started | K21: From existing test TC004
A22: VC-ISS-005 | B22: Priority 2 (Should Have) | C22: Credential Issuance | D22: Schema Management | E22: Verify user can create a new credential schema successfully | F22: User logged into issuer portal | G22: 1. Navigate to Schema section 2. Click Create New Schema 3. Enter schema details 4. Add required fields 5. Click Save | H22: Schema created successfully, appears in schema list | I22: E2E | J22: Not Started | K22: From existing test TC019
A23: VC-ISS-006 | B23: Priority 2 (Should Have) | C23: Credential Issuance | D23: Schema Validation | E23: Validate adding duplicate attribute names in schema | F23: User creating new schema | G23: 1. Add attribute with name "studentId" 2. Attempt to add another attribute with same name 3. Try to save | H23: Error: "Duplicate attribute names not allowed" | I23: Integration | J23: Not Started | K23: From existing test TC022
A24: VC-ISS-007 | B24: Priority 2 (Should Have) | C24: Credential Issuance | D24: Single Issuance | E24: Validate issuance creation with valid data | F24: Schema and template exist | G24: 1. Select credential schema 2. Enter all required fields 3. Enter credentialSubject data 4. Click Issue | H24: Credential issued successfully, stored with unique ID | I24: E2E | J24: Not Started | K24: From existing test TC027
A25: VC-ISS-008 | B25: Priority 2 (Should Have) | C25: Credential Issuance | D25: Data Validation | E25: Validate mandatory fields in issuance | F25: User creating new credential | G25: 1. Leave mandatory field empty 2. Fill other fields 3. Attempt to issue | H25: Error: "Required field [field_name] is missing" | I25: Integration | J25: Not Started | K25: From existing test TC028
A26: VC-ISS-009 | B26: Priority 2 (Should Have) | C26: Credential Issuance | D26: Bulk Operations | E26: Upload correctly filled CSV for bulk issuance | F26: Valid CSV file prepared with credential data | G26: 1. Navigate to bulk issuance 2. Upload CSV file 3. Validate file format 4. Click Process | H26: All credentials from CSV issued successfully | I26: E2E | J26: Not Started | K26: From existing test TC039
A27: VC-ISS-010 | B27: Priority 2 (Should Have) | C27: Credential Issuance | D27: File Validation | E27: Verify that user can upload CSV file only | F27: User on bulk issuance page | G27: 1. Attempt to upload .xlsx file 2. Attempt to upload .txt file 3. Attempt to upload .csv file | H27: Only CSV file accepted, others rejected with error | I27: Integration | J27: Not Started | K27: From existing test TC040
A28: VC-ISS-011 | B28: Priority 2 (Should Have) | C28: Credential Issuance | D28: Revocation | E28: Validate revoke functionality | F28: Issued credential exists | G28: 1. Navigate to issued credentials list 2. Select credential 3. Click Revoke 4. Confirm revocation 5. Update status list | H28: Credential revoked, status updated in StatusList2021 | I28: E2E | J28: Not Started | K28: From existing test TC034
A29: VC-ISS-012 | B29: Priority 2 (Should Have) | C29: Credential Issuance | D29: Revocation | E29: Validate revoke action on already revoked credential | F29: Credential already revoked | G29: 1. Select already revoked credential 2. Attempt to revoke again | H29: Error: "Credential is already revoked" | I29: Integration | J29: Not Started | K29: From existing test TC035
... A49: VC-WALLET-011 | B49: Priority 2 (Should Have) | C49: Mobile Wallet | D49: Network | E49: Verify app behavior when network drops during OTP verification | F49: User attempting OTP verification | G49: 1. Initiate credential download 2. Request OTP 3. Disconnect network 4. Enter OTP 5. Observe behavior | H49: Appropriate error message, retry mechanism available | I49: E2E | J49: Not Started | K49: From existing test TC020

Sheet Priority 3 - Enhanced
A1: Test Case ID | B1: Priority | C1: Category | D1: Component | E1: Test Case Description | F1: Preconditions | G1: Test Steps | H1: Expected Results | I1: Test Type | J1: Status | K1: Notes
A2: VC-PERF-001 | B2: Priority 3 (Nice to Have) | C2: Performance & Scale | D2: Throughput | E2: Verify concurrent verification throughput | F2: 100 concurrent verifiers | G2: 1. Simulate 100 verifiers checking credentials simultaneously 2. Measure response time 3. Check for errors | H2: All verifications complete within 5 seconds, no errors | I2: E2E | J2: Not Started
A3: VC-PERF-002 | B3: Priority 3 (Nice to Have) | C3: Performance & Scale | D3: Bulk Operations | E3: Verify bulk issuance performance | F3: CSV with 10,000 credentials | G3: 1. Upload CSV for bulk issuance 2. Monitor processing time 3. Check success rate | H3: All 10,000 credentials issued within 10 minutes, >99% success | I3: E2E | J3: Not Started
A4: VC-PERF-003 | B4: Priority 3 (Nice to Have) | C4: Performance & Scale | D4: Large Credentials | E4: Verify large credential handling | F4: Credential with 200 claims/fields | G4: 1. Issue very large credential 2. Verify credential 3. Display in wallet 4. Measure performance | H4: All operations complete without timeout | I4: E2E | J4: Not Started
A5: VC-PRIV-001 | B5: Priority 3 (Nice to Have) | C5: Security & Privacy | D5: Error Messages | E5: Verify no PII in error messages | F5: Invalid credential with personal data | G5: 1. Submit invalid credential 2. Check error message content 3. Review logs | H5: Error message generic, no PII exposed | I5: Unit | J5: Not Started
A6: VC-PRIV-002 | B6: Priority 3 (Nice to Have) | C6: Security & Privacy | D6: Minimal Disclosure | E6: Verify minimal disclosure in QR code | F6: QR code generation from credential | G6: 1. Generate QR code from credential 2. Decode QR code content 3. Check what data is included | H6: QR contains only reference/URL, not full credential data | I6: Integration | J6: Not Started
A7: VC-PRIV-003 | B7: Priority 3 (Nice to Have) | C7: Security & Privacy | D7: Selective Disclosure | E7: Verify selective disclosure (if using SD-JWT) | F7: SD-JWT credential with multiple claims | G7: 1. Create presentation with only specific fields 2. Exclude other fields 3. Verify presentation | H7: Only disclosed claims verified, others not revealed | I7: Integration | J7: Not Started
A8: VC-MOBILE-SEC-001 | B8: Priority 3 (Nice to Have) | C8: Security & Privacy | D8: Device Security | E8: Verify rooted/jailbroken device detection | F8: App installed on compromised device | G8: 1. Install wallet on rooted Android device 2. Launch app 3. Check security validation | H8: App detects root, displays warning or refuses to run | I8: Manual | J8: Not Started | K8: Requires physical device
A9: VC-MOBILE-SEC-002 | B9: Priority 3 (Nice to Have) | C9: Security & Privacy | D9: Biometrics | E9: Verify biometric authentication failure handling | F9: Biometric auth enabled | G9: 1. Attempt biometric auth 5 times with wrong fingerprint 2. Check fallback mechanism | H9: Falls back to PIN after failed attempts | I9: Manual | J9: Not Started | K9: Requires physical device
A10: VC-MOBILE-SEC-003 | B10: Priority 3 (Nice to Have) | C10: Security & Privacy | D10: Key Storage | E10: Verify secure key storage | F10: Wallet generates private keys | G10: 1. Generate key pair in wallet 2. Check key storage location 3. Attempt to extract key | H10: Keys stored in Keychain/Keystore, cannot be extracted | I10: Manual | J10: Not Started | K10: Requires forensics
A11: VC-MOBILE-SEC-004 | B11: Priority 3 (Nice to Have) | C11: Security & Privacy | D11: Screen Capture | E11: Verify screen capture prevention | F11: Sensitive credential displayed | G11: 1. Display credential with PII 2. Attempt screenshot 3. Check if blocked | H11: Screenshot blocked or image shows blank screen | I11: Manual | J11: Not Started | K11: Requires physical device
A12: VC-NEG-001 | B12: Priority 3 (Nice to Have) | C12: Security & Privacy | D12: SQL Injection | E12: Verify SQL injection in search | F12: Search functionality in system | G12: 1. Enter search query with SQL injection attempt 2. Submit search | H12: Query properly sanitized, no SQL execution | I12: Manual | J12: Not Started | K12: Security testing
A13: VC-NEG-002 | B13: Priority 3 (Nice to Have) | C13: Security & Privacy | D13: XSS | E13: Verify XSS in credential display | F13: Credential with malicious script in field | G13: 1. Issue credential with script in name field 2. Display credential | H13: Script properly escaped, not executed | I13: Manual | J13: Not Started | K13: Security testing
A14: VC-NEG-003 | B14: Priority 3 (Nice to Have) | C14: Security & Privacy | D14: CSRF | E14: Verify CSRF protection | F14: Admin portal action | G14: 1. Craft malicious request without CSRF token 2. Submit to action endpoint | H14: Request rejected, CSRF protection active | I14: Manual | J14: Not Started | K14: Security testing
A15: VC-COMP-001 | B15: Priority 3 (Nice to Have) | C15: Compliance | D15: Data Protection | E15: Verify right to erasure (GDPR/similar) | F15: User requests credential deletion | G15: 1. User submits deletion request 2. System removes credential and related data 3. Check audit logs 4. Attempt to retrieve deleted data | H15: All personal data removed, audit log shows deletion event | I15: E2E | J15: Not Started
A16: VC-COMP-002 | B16: Priority 3 (Nice to Have) | C16: Compliance | D16: Data Retention | E16: Verify data retention policy enforcement | F16: Audit logs older than retention period | G16: 1. System runs retention policy job 2. Old logs archived/deleted 3. Verify compliance | H16: Old logs archived, retention policy enforced | I16: Integration | J16: Not Started
A17: VC-BIZ-001 | B17: Priority 3 (Nice to Have) | C17: Business Logic | D17: Versioning | E17: Verify credential superseding | F17: Updated credential issued for same subject | G17: 1. Issue credential v1 2. Issue credential v2 (updated information) 3. Both credentials valid 4. Determine which is current | H17: System identifies v2 as current, v1 as superseded | I17: Unit | J17: Not Started
A18: VC-BIZ-002 | B18: Priority 3 (Nice to Have) | C18: Business Logic | D18: Usage Restrictions | E18: Verify conditional credential validity | F18: Credential valid only in certain contexts | G18: 1. Credential includes usage restriction metadata 2. Attempt use outside allowed context | H18: Verifier enforces usage restrictions | I18: Unit | J18: Not Started
A19: VC-RESIL-001 | B19: Priority 3 (Nice to Have) | C19: Resilience | D19: Failover | E19: Verify database failover | F19: Primary database fails | G19: 1. Simulate primary DB failure 2. System fails over to replica 3. Continue credential operations | H19: Seamless failover, operations continue | I19: Integration | J19: Not Started
A20: VC-RESIL-002 | B20: Priority 3 (Nice to Have) | C20: Resilience | D20: Backup & Restore | E20: Verify credential recovery from backup | F20: Wallet backup exists | G20: 1. Delete wallet app 2. Reinstall app 3. Restore from backup | H20: All credentials restored successfully | I20: E2E | J20: Not Started
A21: VC-VER-005 | B21: Priority 3 (Nice to Have) | C21: Credential Verification | D21: Performance | E21: Verify QR code scanning speed and performance under load | F21: Multiple QR codes for scanning | G21: 1. Scan 10 QR codes in succession 2. Measure time per scan 3. Check for degradation | H21: System handles multiple scans without performance degradation | I21: E2E | J21: Not Started | K21: From existing test TC005
